<mujoco model="box">
  <compiler angle="radian" coordinate="local" inertiafromgeom="true" settotalmass="1"/>
  <default>
    <joint armature=".1" damping=".01" limited="false" solimplimit="0 .8 .03" solreflimit=".02 1" stiffness="1"/>
    <geom conaffinity="0" condim="3" contype="1" friction=".0 .0 .0" rgba="0.8 0.6 .4 1" solimp="0.0 0.8 0.01" solref="0.02 1"/>
    <motor ctrllimited="true" ctrlrange="-1 1"/>
  </default>
  <size nstack="300000" nuser_geom="1"/>
  <option gravity="0 0 -9.81" timestep="0.1"/>
  <asset>
    <texture builtin="gradient" height="100" rgb1="1 1 1" rgb2="0 0 0" type="skybox" width="100"/>
    <texture builtin="flat" height="1278" mark="cross" markrgb="1 1 1" name="texgeom" random="0.01" rgb1="0.8 0.6 0.4" rgb2="0.8 0.6 0.4" type="cube" width="127"/>
    <texture builtin="checker" height="100" name="texplane" rgb1="0 0 0" rgb2="0.8 0.8 0.8" type="2d" width="100"/>
    <material name="MatPlane" reflectance="0.5" shininess="1" specular="1" texrepeat="40 40" texture="texplane"/>
    <material name="geom" texture="texgeom" texuniform="true"/>
  </asset>
  <worldbody>
    <light cutoff="100" diffuse="1 1 1" dir="-0 0 -1.3" directional="true" exponent="1" pos="0 0 1.3" specular=".1 .1 .1"/>
    <geom conaffinity="1" condim="3" material="MatPlane" name="floor" pos="0 0 0" rgba="0.8 0.9 0.8 1" size="40 40 40" type="plane"/>
    <body name="box" pos="0 0 0">
      <camera name="track" mode="trackcom" pos="0 -9 3" xyaxes="1 0 0 0 0.3 1"/>
      <geom type="sphere" size="0.1 0.1 0.1" rgba="0 0 1 1"/>
      <joint axis="1 0 0" damping="1" name="boxslideX" pos="0 0 0" range="-30 30" stiffness="1"  type="slide" />
      <joint axis="0 1 0" damping="1" name="boxslideY" pos="0 0 0" range="-30 30" stiffness="1"  type="slide" />
      <!-- <joint name="boxslideZ" type="slide" axis="0 0 1" limited="false"/> -->
      <!-- Dummy body for visualizing desired orientation -->
      <!-- <body name="dummy_orientation_body" pos="0.2 0 0.1">
        <joint name="boxrotateY" type="hinge" axis="0 1 0" limited="false"/>
        <geom name="orientation_bar" type="cylinder" size="0.02 0.1" rgba="1 0 0 1" contype="0" conaffinity="0"/>
      </body> -->
    </body>
  </worldbody>
  <actuator>
    <motor gear="200" joint="boxslideX" name="box_move_x"/>
    <motor gear="200" joint="boxslideY" name="box_move_y"/>
    <!-- <motor gear="100" joint="boxrotateY" name="box_rotate_y"/>
    <motor gear="100" joint="boxslideZ" name="box_move_z"/> -->
    <!-- <motor gear="0" joint="boxslideX" name="box_dummy_x"/> -->
    <!-- <motor gear="0" joint="boxslideZ" name="box_dummy_z"/> -->
  </actuator>
</mujoco>